<?xml version="1.0" encoding="utf-8"?>
<!-- This URDF was automatically created by SolidWorks to URDF Exporter! Originally created by Stephen Brawner (brawner@gmail.com) 
     Commit Version: 1.6.0-4-g7f85cfe  Build Version: 1.6.7995.38578
     For more information, please see http://wiki.ros.org/sw_urdf_exporter -->
<robot
  name="Simplified Rover.SLDASM">
  <link
    name="base_link">
    <inertial>
      <origin
        xyz="0.00576475076698013 -0.000282621352115014 -0.0254987349464202"
        rpy="0 0 0" />
      <mass
        value="1.88538793284251" />
      <inertia
        ixx="0.0132728168369738"
        ixy="4.61289523752377E-07"
        ixz="-5.9035519634991E-06"
        iyy="0.042111764464268"
        iyz="5.08066054412427E-08"
        izz="0.0541085186542932" />
    </inertial>
    <visual>
      <origin
        xyz="0 0 0"
        rpy="0 0 0" />
      <geometry>
        <mesh
          filename="package://Simplified Rover.SLDASM/meshes/base_link.STL" />
      </geometry>
      <material
        name="">
        <color
          rgba="0.792156862745098 0.819607843137255 0.933333333333333 1" />
      </material>
    </visual>
    <collision>
      <origin
        xyz="0 0 0"
        rpy="0 0 0" />
      <geometry>
        <mesh
          filename="package://Simplified Rover.SLDASM/meshes/base_link.STL" />
      </geometry>
    </collision>
  </link>
  <link
    name="FL_Link">
    <inertial>
      <origin
        xyz="0.0034562 -0.030782 -0.0002313"
        rpy="0 0 0" />
      <mass
        value="0.62031" />
      <inertia
        ixx="0.0028703"
        ixy="-0.00025171"
        ixz="-2.1254E-06"
        iyy="0.005086"
        iyz="1.6644E-05"
        izz="0.0028421" />
    </inertial>
    <visual>
      <origin
        xyz="0 0 0"
        rpy="0 0 0" />
      <geometry>
        <mesh
          filename="package://Simplified Rover.SLDASM/meshes/FL_Link.STL" />
      </geometry>
      <material
        name="">
        <color
          rgba="0.79216 0.81961 0.93333 1" />
      </material>
    </visual>
    <collision>
      <origin
        xyz="0 0 0"
        rpy="0 0 0" />
      <geometry>
        <mesh
          filename="package://Simplified Rover.SLDASM/meshes/FL_Link.STL" />
      </geometry>
    </collision>
  </link>
  <joint
    name="FL_Joint"
    type="continuous">
    <origin
      xyz="0.46435 0.33806 -0.36495"
      rpy="0 0 0" />
    <parent
      link="base_link" />
    <child
      link="FL_Link" />
    <axis
      xyz="0 1 0" />
  </joint>
  <link
    name="FR_Link">
    <inertial>
      <origin
        xyz="0.0057715 0.030434 -0.00011696"
        rpy="0 0 0" />
      <mass
        value="0.62031" />
      <inertia
        ixx="0.0029208"
        ixy="0.00041578"
        ixz="-1.3826E-06"
        iyy="0.0050355"
        iyz="-8.6937E-06"
        izz="0.0028421" />
    </inertial>
    <visual>
      <origin
        xyz="0 0 0"
        rpy="0 0 0" />
      <geometry>
        <mesh
          filename="package://Simplified Rover.SLDASM/meshes/FR_Link.STL" />
      </geometry>
      <material
        name="">
        <color
          rgba="0.79216 0.81961 0.93333 1" />
      </material>
    </visual>
    <collision>
      <origin
        xyz="0 0 0"
        rpy="0 0 0" />
      <geometry>
        <mesh
          filename="package://Simplified Rover.SLDASM/meshes/FR_Link.STL" />
      </geometry>
    </collision>
  </link>
  <joint
    name="FR_Joint"
    type="continuous">
    <origin
      xyz="0.47521 -0.33771 -0.35104"
      rpy="0 0 0" />
    <parent
      link="base_link" />
    <child
      link="FR_Link" />
    <axis
      xyz="0 1 0" />
  </joint>
  <link
    name="BL_Link">
    <inertial>
      <origin
        xyz="-0.00028074 -0.030975 1.4632E-05"
        rpy="0 0 0" />
      <mass
        value="0.62031" />
      <inertia
        ixx="0.002842"
        ixy="2.0659E-05"
        ixz="-1.1565E-07"
        iyy="0.0051142"
        iyz="-1.366E-06"
        izz="0.0028423" />
    </inertial>
    <visual>
      <origin
        xyz="0 0 0"
        rpy="0 0 0" />
      <geometry>
        <mesh
          filename="package://Simplified Rover.SLDASM/meshes/BL_Link.STL" />
      </geometry>
      <material
        name="">
        <color
          rgba="0.79216 0.81961 0.93333 1" />
      </material>
    </visual>
    <collision>
      <origin
        xyz="0 0 0"
        rpy="0 0 0" />
      <geometry>
        <mesh
          filename="package://Simplified Rover.SLDASM/meshes/BL_Link.STL" />
      </geometry>
    </collision>
  </link>
  <joint
    name="BL_Joint"
    type="continuous">
    <origin
      xyz="-0.50437 0.33826 -0.32267"
      rpy="0 0 0" />
    <parent
      link="base_link" />
    <child
      link="BL_Link" />
    <axis
      xyz="0 1 0" />
  </joint>
  <link
    name="BR_Link">
    <inertial>
      <origin
        xyz="0.0057679 0.030435 -0.00012399"
        rpy="0 0 0" />
      <mass
        value="0.62031" />
      <inertia
        ixx="0.0029206"
        ixy="0.00041587"
        ixz="-1.5095E-06"
        iyy="0.0050356"
        iyz="-8.6825E-06"
        izz="0.0028424" />
    </inertial>
    <visual>
      <origin
        xyz="0 0 0"
        rpy="0 0 0" />
      <geometry>
        <mesh
          filename="package://Simplified Rover.SLDASM/meshes/BR_Link.STL" />
      </geometry>
      <material
        name="">
        <color
          rgba="0.79216 0.81961 0.93333 1" />
      </material>
    </visual>
    <collision>
      <origin
        xyz="0 0 0"
        rpy="0 0 0" />
      <geometry>
        <mesh
          filename="package://Simplified Rover.SLDASM/meshes/BR_Link.STL" />
      </geometry>
    </collision>
  </link>
  <joint
    name="BR_Joint"
    type="continuous">
    <origin
      xyz="-0.49861 -0.33771 -0.33765"
      rpy="0 0 0" />
    <parent
      link="base_link" />
    <child
      link="BR_Link" />
    <axis
      xyz="0 1 0" />
  </joint>
  <link
    name="Bottom_EBox_Link">
    <inertial>
      <origin
        xyz="0.012241 0.0062207 0.10763"
        rpy="0 0 0" />
      <mass
        value="2.005" />
      <inertia
        ixx="0.042455"
        ixy="-0.0044655"
        ixz="0.0002535"
        iyy="0.040805"
        iyz="0.00070604"
        izz="0.072752" />
    </inertial>
    <visual>
      <origin
        xyz="0 0 0"
        rpy="0 0 0" />
      <geometry>
        <mesh
          filename="package://Simplified Rover.SLDASM/meshes/Bottom_EBox_Link.STL" />
      </geometry>
      <material
        name="">
        <color
          rgba="0.79216 0.81961 0.93333 1" />
      </material>
    </visual>
    <collision>
      <origin
        xyz="0 0 0"
        rpy="0 0 0" />
      <geometry>
        <mesh
          filename="package://Simplified Rover.SLDASM/meshes/Bottom_EBox_Link.STL" />
      </geometry>
    </collision>
  </link>
  <joint
    name="Bottom_EBox_Joint"
    type="fixed">
    <origin
      xyz="-0.20871 0.0007866 0.011577"
      rpy="0 0 0" />
    <parent
      link="base_link" />
    <child
      link="Bottom_EBox_Link" />
    <axis
      xyz="0 0 0" />
  </joint>
  <link
    name="Camera_Link">
    <inertial>
      <origin
        xyz="0 0 0"
        rpy="0 0 0" />
      <mass
        value="0" />
      <inertia
        ixx="0"
        ixy="0"
        ixz="0"
        iyy="0"
        iyz="0"
        izz="0" />
    </inertial>
    <visual>
      <origin
        xyz="0 0 0"
        rpy="0 0 0" />
      <geometry>
        <mesh
          filename="package://Simplified Rover.SLDASM/meshes/Camera_Link.STL" />
      </geometry>
      <material
        name="">
        <color
          rgba="1 1 1 1" />
      </material>
    </visual>
    <collision>
      <origin
        xyz="0 0 0"
        rpy="0 0 0" />
      <geometry>
        <mesh
          filename="package://Simplified Rover.SLDASM/meshes/Camera_Link.STL" />
      </geometry>
    </collision>
  </link>
  <joint
    name="Camera_Joint"
    type="prismatic">
    <origin
      xyz="0.41296 0 0"
      rpy="0 0 0" />
    <parent
      link="base_link" />
    <child
      link="Camera_Link" />
    <axis
      xyz="0 1 0" />
    <limit
      lower="0"
      upper="0"
      effort="0"
      velocity="0" />
  </joint>
</robot>